<?xml version="1.0" encoding="utf-8"?>
<TestRun id="7092b50d-65cf-4291-8750-527478cbca61" name="@docker-desktop 2025-06-14 15:27:50" xmlns="http://microsoft.com/schemas/VisualStudio/TeamTest/2010">
  <Times creation="2025-06-14T15:27:50.0710991+00:00" queuing="2025-06-14T15:27:50.0710992+00:00" start="2025-06-14T15:27:48.4476751+00:00" finish="2025-06-14T15:27:50.2347170+00:00" />
  <TestSettings name="default" id="9e5c8f03-00b5-48fe-8fa2-0da7526d4599">
    <Deployment runDeploymentRoot="_docker-desktop_2025-06-14_15_27_50" />
  </TestSettings>
  <Results>
    <UnitTestResult executionId="997a2069-1975-4861-b7c1-9d55ca740a91" testId="63595178-fc82-5569-d94c-3932b3f89509" testName="ValidateCreditCard(&quot;Invalid CVV length Visa&quot;,&quot;Clara Wells&quot;,&quot;4111111111111111&quot;,&quot;12&quot;,&quot;12/30&quot;,&quot;400&quot;,&quot;Cvv&quot;,null)" computerName="docker-desktop" duration="00:00:00.0176730" startTime="2025-06-14T15:27:49.9532280+00:00" endTime="2025-06-14T15:27:49.9709005+00:00" testType="13cdc9d9-ddb5-4fa4-a97d-d965ccfc6d4b" outcome="Failed" testListId="8c84fa94-04c1-424b-9868-57a2d4851a1d" relativeResultsDirectory="997a2069-1975-4861-b7c1-9d55ca740a91">
      <Output>
        <StdOut>Given this is test case "Invalid CVV length Visa"
API Base URL: http://localhost:7135
Running test case: Invalid CVV length Visa
-&gt; done: CreditCardValidationSteps.GivenThisIsTestCase("Invalid CVV lengt...") (0.0s)
And I prepare a credit card with:
  --- table step argument ---
  | Owner       | Number           | Cvv | IssueDate |
  | Clara Wells | 4111111111111111 | 12  | 12/30     |
-&gt; done: CreditCardValidationSteps.GivenIPrepareACreditCardWith(&lt;table&gt;) (0.0s)
When I send the card to the validation API
-&gt; done: CreditCardValidationSteps.WhenISendTheCardToTheValidationAPI() (0.0s)
Then the response status should be 400
-&gt; error: Exception has been thrown by the target of an invocation. (0.0s)
And the response body should contain "Cvv"
-&gt; skipped because of previous errors
-&gt; duration: Scenario: Validate Credit Card: 14.7ms</StdOut>
        <ErrorInfo>
          <Message>  Expected HTTP 400, but got 0. Response body: 
Assert.That(actualStatus, Is.EqualTo(expectedStatus))
  Expected: 400
  But was:  0
</Message>
          <StackTrace>   at CardValidation.Tests.Steps.CreditCardValidationSteps.__a$_around_ThenTheResponseStatusShouldBe_100663316_o(Int32 expectedStatus) in /app/CardValidation.Tests/Steps/CreditCardValidationSteps.cs:line 88
   at CardValidation.Tests.Steps.CreditCardValidationSteps.__a$_around_ThenTheResponseStatusShouldBe_100663316_u(Object[])
   at Allure.Net.Commons.Steps.AllureAbstractStepAspect.WrapSyncVoid(Func`2 target, Object[] args, MethodBase metadata, String stepName, List`1 stepParameters)
   at InvokeStub_AllureAbstractStepAspect.WrapSyncVoid(Object, Span`1)

1)    at CardValidation.Tests.Steps.CreditCardValidationSteps.__a$_around_ThenTheResponseStatusShouldBe_100663316_o(Int32 expectedStatus) in /app/CardValidation.Tests/Steps/CreditCardValidationSteps.cs:line 88
   at CardValidation.Tests.Steps.CreditCardValidationSteps.__a$_around_ThenTheResponseStatusShouldBe_100663316_u(Object[])
   at Allure.Net.Commons.Steps.AllureAbstractStepAspect.WrapSyncVoid(Func`2 target, Object[] args, MethodBase metadata, String stepName, List`1 stepParameters)
   at InvokeStub_AllureAbstractStepAspect.WrapSyncVoid(Object, Span`1)

</StackTrace>
        </ErrorInfo>
      </Output>
    </UnitTestResult>
    <UnitTestResult executionId="36fe9e01-08a8-4b29-a0c2-39b966544754" testId="f1411156-fa3a-66fd-3aeb-a831f0075505" testName="ValidateCreditCard(&quot;Owner Contains Number&quot;,&quot;Jane 4111&quot;,&quot;4111111111111111&quot;,&quot;123&quot;,&quot;12/30&quot;,&quot;400&quot;,&quot;Owner&quot;,null)" computerName="docker-desktop" duration="00:00:00.0187640" startTime="2025-06-14T15:27:49.9959301+00:00" endTime="2025-06-14T15:27:50.0146942+00:00" testType="13cdc9d9-ddb5-4fa4-a97d-d965ccfc6d4b" outcome="Failed" testListId="8c84fa94-04c1-424b-9868-57a2d4851a1d" relativeResultsDirectory="36fe9e01-08a8-4b29-a0c2-39b966544754">
      <Output>
        <StdOut>Given this is test case "Owner Contains Number"
API Base URL: http://localhost:7135
Running test case: Owner Contains Number
-&gt; done: CreditCardValidationSteps.GivenThisIsTestCase("Owner Contains Nu...") (0.0s)
And I prepare a credit card with:
  --- table step argument ---
  | Owner     | Number           | Cvv | IssueDate |
  | Jane 4111 | 4111111111111111 | 123 | 12/30     |
-&gt; done: CreditCardValidationSteps.GivenIPrepareACreditCardWith(&lt;table&gt;) (0.0s)
When I send the card to the validation API
-&gt; done: CreditCardValidationSteps.WhenISendTheCardToTheValidationAPI() (0.0s)
Then the response status should be 400
-&gt; error: Exception has been thrown by the target of an invocation. (0.0s)
And the response body should contain "Owner"
-&gt; skipped because of previous errors
-&gt; duration: Scenario: Validate Credit Card: 15.9ms</StdOut>
        <ErrorInfo>
          <Message>  Expected HTTP 400, but got 0. Response body: 
Assert.That(actualStatus, Is.EqualTo(expectedStatus))
  Expected: 400
  But was:  0
</Message>
          <StackTrace>   at CardValidation.Tests.Steps.CreditCardValidationSteps.__a$_around_ThenTheResponseStatusShouldBe_100663316_o(Int32 expectedStatus) in /app/CardValidation.Tests/Steps/CreditCardValidationSteps.cs:line 88
   at CardValidation.Tests.Steps.CreditCardValidationSteps.__a$_around_ThenTheResponseStatusShouldBe_100663316_u(Object[])
   at Allure.Net.Commons.Steps.AllureAbstractStepAspect.WrapSyncVoid(Func`2 target, Object[] args, MethodBase metadata, String stepName, List`1 stepParameters)
   at InvokeStub_AllureAbstractStepAspect.WrapSyncVoid(Object, Span`1)

1)    at CardValidation.Tests.Steps.CreditCardValidationSteps.__a$_around_ThenTheResponseStatusShouldBe_100663316_o(Int32 expectedStatus) in /app/CardValidation.Tests/Steps/CreditCardValidationSteps.cs:line 88
   at CardValidation.Tests.Steps.CreditCardValidationSteps.__a$_around_ThenTheResponseStatusShouldBe_100663316_u(Object[])
   at Allure.Net.Commons.Steps.AllureAbstractStepAspect.WrapSyncVoid(Func`2 target, Object[] args, MethodBase metadata, String stepName, List`1 stepParameters)
   at InvokeStub_AllureAbstractStepAspect.WrapSyncVoid(Object, Span`1)

</StackTrace>
        </ErrorInfo>
      </Output>
    </UnitTestResult>
    <UnitTestResult executionId="85c17475-5bd8-4ffd-9321-967aee1449ff" testId="59baaf00-14ab-9c15-2cf3-9c9f8aaf579c" testName="ValidateCreditCard(&quot;Owner Contains Card Number&quot;,&quot;John 4111111&quot;,&quot;4111111111111111&quot;,&quot;123&quot;,&quot;12/30&quot;,&quot;400&quot;,&quot;Owner&quot;,null)" computerName="docker-desktop" duration="00:00:00.0162610" startTime="2025-06-14T15:27:50.0147445+00:00" endTime="2025-06-14T15:27:50.0310047+00:00" testType="13cdc9d9-ddb5-4fa4-a97d-d965ccfc6d4b" outcome="Failed" testListId="8c84fa94-04c1-424b-9868-57a2d4851a1d" relativeResultsDirectory="85c17475-5bd8-4ffd-9321-967aee1449ff">
      <Output>
        <StdOut>Given this is test case "Owner Contains Card Number"
API Base URL: http://localhost:7135
Running test case: Owner Contains Card Number
-&gt; done: CreditCardValidationSteps.GivenThisIsTestCase("Owner Contains Ca...") (0.0s)
And I prepare a credit card with:
  --- table step argument ---
  | Owner        | Number           | Cvv | IssueDate |
  | John 4111111 | 4111111111111111 | 123 | 12/30     |
-&gt; done: CreditCardValidationSteps.GivenIPrepareACreditCardWith(&lt;table&gt;) (0.0s)
When I send the card to the validation API
-&gt; done: CreditCardValidationSteps.WhenISendTheCardToTheValidationAPI() (0.0s)
Then the response status should be 400
-&gt; error: Exception has been thrown by the target of an invocation. (0.0s)
And the response body should contain "Owner"
-&gt; skipped because of previous errors
-&gt; duration: Scenario: Validate Credit Card: 13.8ms</StdOut>
        <ErrorInfo>
          <Message>  Expected HTTP 400, but got 0. Response body: 
Assert.That(actualStatus, Is.EqualTo(expectedStatus))
  Expected: 400
  But was:  0
</Message>
          <StackTrace>   at CardValidation.Tests.Steps.CreditCardValidationSteps.__a$_around_ThenTheResponseStatusShouldBe_100663316_o(Int32 expectedStatus) in /app/CardValidation.Tests/Steps/CreditCardValidationSteps.cs:line 88
   at CardValidation.Tests.Steps.CreditCardValidationSteps.__a$_around_ThenTheResponseStatusShouldBe_100663316_u(Object[])
   at Allure.Net.Commons.Steps.AllureAbstractStepAspect.WrapSyncVoid(Func`2 target, Object[] args, MethodBase metadata, String stepName, List`1 stepParameters)
   at InvokeStub_AllureAbstractStepAspect.WrapSyncVoid(Object, Span`1)

1)    at CardValidation.Tests.Steps.CreditCardValidationSteps.__a$_around_ThenTheResponseStatusShouldBe_100663316_o(Int32 expectedStatus) in /app/CardValidation.Tests/Steps/CreditCardValidationSteps.cs:line 88
   at CardValidation.Tests.Steps.CreditCardValidationSteps.__a$_around_ThenTheResponseStatusShouldBe_100663316_u(Object[])
   at Allure.Net.Commons.Steps.AllureAbstractStepAspect.WrapSyncVoid(Func`2 target, Object[] args, MethodBase metadata, String stepName, List`1 stepParameters)
   at InvokeStub_AllureAbstractStepAspect.WrapSyncVoid(Object, Span`1)

</StackTrace>
        </ErrorInfo>
      </Output>
    </UnitTestResult>
    <UnitTestResult executionId="67c27c6f-0e64-4220-acba-922a6b46bf3c" testId="7b4e6a07-dd17-f5f2-ca6e-26619edc7e8c" testName="ValidateCreditCard(&quot;Missing Owner&quot;,&quot;&quot;,&quot;4111111111111111&quot;,&quot;123&quot;,&quot;12/30&quot;,&quot;400&quot;,&quot;Owner&quot;,null)" computerName="docker-desktop" duration="00:00:00.0183830" startTime="2025-06-14T15:27:49.8675020+00:00" endTime="2025-06-14T15:27:49.8858844+00:00" testType="13cdc9d9-ddb5-4fa4-a97d-d965ccfc6d4b" outcome="Failed" testListId="8c84fa94-04c1-424b-9868-57a2d4851a1d" relativeResultsDirectory="67c27c6f-0e64-4220-acba-922a6b46bf3c">
      <Output>
        <StdOut>Given this is test case "Missing Owner"
API Base URL: http://localhost:7135
Running test case: Missing Owner
-&gt; done: CreditCardValidationSteps.GivenThisIsTestCase("Missing Owner") (0.0s)
And I prepare a credit card with:
  --- table step argument ---
  | Owner | Number           | Cvv | IssueDate |
  |       | 4111111111111111 | 123 | 12/30     |
-&gt; done: CreditCardValidationSteps.GivenIPrepareACreditCardWith(&lt;table&gt;) (0.0s)
When I send the card to the validation API
-&gt; done: CreditCardValidationSteps.WhenISendTheCardToTheValidationAPI() (0.0s)
Then the response status should be 400
-&gt; error: Exception has been thrown by the target of an invocation. (0.0s)
And the response body should contain "Owner"
-&gt; skipped because of previous errors
-&gt; duration: Scenario: Validate Credit Card: 16.2ms</StdOut>
        <ErrorInfo>
          <Message>  Expected HTTP 400, but got 0. Response body: 
Assert.That(actualStatus, Is.EqualTo(expectedStatus))
  Expected: 400
  But was:  0
</Message>
          <StackTrace>   at CardValidation.Tests.Steps.CreditCardValidationSteps.__a$_around_ThenTheResponseStatusShouldBe_100663316_o(Int32 expectedStatus) in /app/CardValidation.Tests/Steps/CreditCardValidationSteps.cs:line 88
   at CardValidation.Tests.Steps.CreditCardValidationSteps.__a$_around_ThenTheResponseStatusShouldBe_100663316_u(Object[])
   at Allure.Net.Commons.Steps.AllureAbstractStepAspect.WrapSyncVoid(Func`2 target, Object[] args, MethodBase metadata, String stepName, List`1 stepParameters)
   at InvokeStub_AllureAbstractStepAspect.WrapSyncVoid(Object, Span`1)

1)    at CardValidation.Tests.Steps.CreditCardValidationSteps.__a$_around_ThenTheResponseStatusShouldBe_100663316_o(Int32 expectedStatus) in /app/CardValidation.Tests/Steps/CreditCardValidationSteps.cs:line 88
   at CardValidation.Tests.Steps.CreditCardValidationSteps.__a$_around_ThenTheResponseStatusShouldBe_100663316_u(Object[])
   at Allure.Net.Commons.Steps.AllureAbstractStepAspect.WrapSyncVoid(Func`2 target, Object[] args, MethodBase metadata, String stepName, List`1 stepParameters)
   at InvokeStub_AllureAbstractStepAspect.WrapSyncVoid(Object, Span`1)

</StackTrace>
        </ErrorInfo>
      </Output>
    </UnitTestResult>
    <UnitTestResult executionId="9fbecdf1-666d-4932-9433-8e1c4d57130e" testId="470e68ea-e419-d394-555b-a31ecfd65e61" testName="ValidateCreditCard(&quot;Invalid Owner and CVV&quot;,&quot;John 123&quot;,&quot;4111111111111111&quot;,&quot;12&quot;,&quot;12/30&quot;,&quot;400&quot;,&quot;{\&quot;Cvv\&quot;:[\&quot;Wrong cvv\&quot;],\&quot;Owner\&quot;:[\&quot;Wrong owner\&quot;]}&quot;,null)" computerName="docker-desktop" duration="00:00:00.0185010" startTime="2025-06-14T15:27:50.0903334+00:00" endTime="2025-06-14T15:27:50.1088348+00:00" testType="13cdc9d9-ddb5-4fa4-a97d-d965ccfc6d4b" outcome="Failed" testListId="8c84fa94-04c1-424b-9868-57a2d4851a1d" relativeResultsDirectory="9fbecdf1-666d-4932-9433-8e1c4d57130e">
      <Output>
        <StdOut>Given this is test case "Invalid Owner and CVV"
API Base URL: http://localhost:7135
Running test case: Invalid Owner and CVV
-&gt; done: CreditCardValidationSteps.GivenThisIsTestCase("Invalid Owner and...") (0.0s)
And I prepare a credit card with:
  --- table step argument ---
  | Owner    | Number           | Cvv | IssueDate |
  | John 123 | 4111111111111111 | 12  | 12/30     |
-&gt; done: CreditCardValidationSteps.GivenIPrepareACreditCardWith(&lt;table&gt;) (0.0s)
When I send the card to the validation API
-&gt; done: CreditCardValidationSteps.WhenISendTheCardToTheValidationAPI() (0.0s)
Then the response status should be 400
-&gt; error: Exception has been thrown by the target of an invocation. (0.0s)
And the response body should contain "{"Cvv":["Wrong cvv"],"Owner":["Wrong owner"]}"
-&gt; skipped because of previous errors
-&gt; duration: Scenario: Validate Credit Card: 15.8ms</StdOut>
        <ErrorInfo>
          <Message>  Expected HTTP 400, but got 0. Response body: 
Assert.That(actualStatus, Is.EqualTo(expectedStatus))
  Expected: 400
  But was:  0
</Message>
          <StackTrace>   at CardValidation.Tests.Steps.CreditCardValidationSteps.__a$_around_ThenTheResponseStatusShouldBe_100663316_o(Int32 expectedStatus) in /app/CardValidation.Tests/Steps/CreditCardValidationSteps.cs:line 88
   at CardValidation.Tests.Steps.CreditCardValidationSteps.__a$_around_ThenTheResponseStatusShouldBe_100663316_u(Object[])
   at Allure.Net.Commons.Steps.AllureAbstractStepAspect.WrapSyncVoid(Func`2 target, Object[] args, MethodBase metadata, String stepName, List`1 stepParameters)
   at InvokeStub_AllureAbstractStepAspect.WrapSyncVoid(Object, Span`1)

1)    at CardValidation.Tests.Steps.CreditCardValidationSteps.__a$_around_ThenTheResponseStatusShouldBe_100663316_o(Int32 expectedStatus) in /app/CardValidation.Tests/Steps/CreditCardValidationSteps.cs:line 88
   at CardValidation.Tests.Steps.CreditCardValidationSteps.__a$_around_ThenTheResponseStatusShouldBe_100663316_u(Object[])
   at Allure.Net.Commons.Steps.AllureAbstractStepAspect.WrapSyncVoid(Func`2 target, Object[] args, MethodBase metadata, String stepName, List`1 stepParameters)
   at InvokeStub_AllureAbstractStepAspect.WrapSyncVoid(Object, Span`1)

</StackTrace>
        </ErrorInfo>
      </Output>
    </UnitTestResult>
    <UnitTestResult executionId="04275393-c4ba-451e-968a-fe69dbf59f6e" testId="adc08fa8-fee9-a023-40ff-926214b51695" testName="ValidateCreditCard(&quot;Missing IssueDate&quot;,&quot;Jane Doe&quot;,&quot;4111111111111111&quot;,&quot;123&quot;,&quot;&quot;,&quot;400&quot;,&quot;date&quot;,null)" computerName="docker-desktop" duration="00:00:00.0146340" startTime="2025-06-14T15:27:49.9220707+00:00" endTime="2025-06-14T15:27:49.9367041+00:00" testType="13cdc9d9-ddb5-4fa4-a97d-d965ccfc6d4b" outcome="Failed" testListId="8c84fa94-04c1-424b-9868-57a2d4851a1d" relativeResultsDirectory="04275393-c4ba-451e-968a-fe69dbf59f6e">
      <Output>
        <StdOut>Given this is test case "Missing IssueDate"
API Base URL: http://localhost:7135
Running test case: Missing IssueDate
-&gt; done: CreditCardValidationSteps.GivenThisIsTestCase("Missing IssueDate") (0.0s)
And I prepare a credit card with:
  --- table step argument ---
  | Owner    | Number           | Cvv | IssueDate |
  | Jane Doe | 4111111111111111 | 123 |           |
-&gt; done: CreditCardValidationSteps.GivenIPrepareACreditCardWith(&lt;table&gt;) (0.0s)
When I send the card to the validation API
-&gt; done: CreditCardValidationSteps.WhenISendTheCardToTheValidationAPI() (0.0s)
Then the response status should be 400
-&gt; error: Exception has been thrown by the target of an invocation. (0.0s)
And the response body should contain "date"
-&gt; skipped because of previous errors
-&gt; duration: Scenario: Validate Credit Card: 12.2ms</StdOut>
        <ErrorInfo>
          <Message>  Expected HTTP 400, but got 0. Response body: 
Assert.That(actualStatus, Is.EqualTo(expectedStatus))
  Expected: 400
  But was:  0
</Message>
          <StackTrace>   at CardValidation.Tests.Steps.CreditCardValidationSteps.__a$_around_ThenTheResponseStatusShouldBe_100663316_o(Int32 expectedStatus) in /app/CardValidation.Tests/Steps/CreditCardValidationSteps.cs:line 88
   at CardValidation.Tests.Steps.CreditCardValidationSteps.__a$_around_ThenTheResponseStatusShouldBe_100663316_u(Object[])
   at Allure.Net.Commons.Steps.AllureAbstractStepAspect.WrapSyncVoid(Func`2 target, Object[] args, MethodBase metadata, String stepName, List`1 stepParameters)
   at InvokeStub_AllureAbstractStepAspect.WrapSyncVoid(Object, Span`1)

1)    at CardValidation.Tests.Steps.CreditCardValidationSteps.__a$_around_ThenTheResponseStatusShouldBe_100663316_o(Int32 expectedStatus) in /app/CardValidation.Tests/Steps/CreditCardValidationSteps.cs:line 88
   at CardValidation.Tests.Steps.CreditCardValidationSteps.__a$_around_ThenTheResponseStatusShouldBe_100663316_u(Object[])
   at Allure.Net.Commons.Steps.AllureAbstractStepAspect.WrapSyncVoid(Func`2 target, Object[] args, MethodBase metadata, String stepName, List`1 stepParameters)
   at InvokeStub_AllureAbstractStepAspect.WrapSyncVoid(Object, Span`1)

</StackTrace>
        </ErrorInfo>
      </Output>
    </UnitTestResult>
    <UnitTestResult executionId="b142d5de-7721-42c3-b6ed-18240813de3f" testId="20dc1195-9c36-e5e4-a77d-cef27585349b" testName="ValidateCreditCard(&quot;Missing CVV&quot;,&quot;Jane Doe&quot;,&quot;4111111111111111&quot;,&quot;&quot;,&quot;12/30&quot;,&quot;400&quot;,&quot;Cvv&quot;,null)" computerName="docker-desktop" duration="00:00:00.0213330" startTime="2025-06-14T15:27:49.9006964+00:00" endTime="2025-06-14T15:27:49.9220292+00:00" testType="13cdc9d9-ddb5-4fa4-a97d-d965ccfc6d4b" outcome="Failed" testListId="8c84fa94-04c1-424b-9868-57a2d4851a1d" relativeResultsDirectory="b142d5de-7721-42c3-b6ed-18240813de3f">
      <Output>
        <StdOut>Given this is test case "Missing CVV"
API Base URL: http://localhost:7135
Running test case: Missing CVV
-&gt; done: CreditCardValidationSteps.GivenThisIsTestCase("Missing CVV") (0.0s)
And I prepare a credit card with:
  --- table step argument ---
  | Owner    | Number           | Cvv | IssueDate |
  | Jane Doe | 4111111111111111 |     | 12/30     |
-&gt; done: CreditCardValidationSteps.GivenIPrepareACreditCardWith(&lt;table&gt;) (0.0s)
When I send the card to the validation API
-&gt; done: CreditCardValidationSteps.WhenISendTheCardToTheValidationAPI() (0.0s)
Then the response status should be 400
-&gt; error: Exception has been thrown by the target of an invocation. (0.0s)
And the response body should contain "Cvv"
-&gt; skipped because of previous errors
-&gt; duration: Scenario: Validate Credit Card: 19.0ms</StdOut>
        <ErrorInfo>
          <Message>  Expected HTTP 400, but got 0. Response body: 
Assert.That(actualStatus, Is.EqualTo(expectedStatus))
  Expected: 400
  But was:  0
</Message>
          <StackTrace>   at CardValidation.Tests.Steps.CreditCardValidationSteps.__a$_around_ThenTheResponseStatusShouldBe_100663316_o(Int32 expectedStatus) in /app/CardValidation.Tests/Steps/CreditCardValidationSteps.cs:line 88
   at CardValidation.Tests.Steps.CreditCardValidationSteps.__a$_around_ThenTheResponseStatusShouldBe_100663316_u(Object[])
   at Allure.Net.Commons.Steps.AllureAbstractStepAspect.WrapSyncVoid(Func`2 target, Object[] args, MethodBase metadata, String stepName, List`1 stepParameters)
   at InvokeStub_AllureAbstractStepAspect.WrapSyncVoid(Object, Span`1)

1)    at CardValidation.Tests.Steps.CreditCardValidationSteps.__a$_around_ThenTheResponseStatusShouldBe_100663316_o(Int32 expectedStatus) in /app/CardValidation.Tests/Steps/CreditCardValidationSteps.cs:line 88
   at CardValidation.Tests.Steps.CreditCardValidationSteps.__a$_around_ThenTheResponseStatusShouldBe_100663316_u(Object[])
   at Allure.Net.Commons.Steps.AllureAbstractStepAspect.WrapSyncVoid(Func`2 target, Object[] args, MethodBase metadata, String stepName, List`1 stepParameters)
   at InvokeStub_AllureAbstractStepAspect.WrapSyncVoid(Object, Span`1)

</StackTrace>
        </ErrorInfo>
      </Output>
    </UnitTestResult>
    <UnitTestResult executionId="1934ec9b-2319-458f-b8ec-90db595efd44" testId="68ca3ca2-1c1d-512a-bc13-db3d73a443a6" testName="ValidateCreditCard(&quot;CVV with special chars&quot;,&quot;Jane Doe&quot;,&quot;4111111111111111&quot;,&quot;12@#&quot;,&quot;12/30&quot;,&quot;400&quot;,&quot;Cvv&quot;,null)" computerName="docker-desktop" duration="00:00:00.0233970" startTime="2025-06-14T15:27:50.0310538+00:00" endTime="2025-06-14T15:27:50.0544506+00:00" testType="13cdc9d9-ddb5-4fa4-a97d-d965ccfc6d4b" outcome="Failed" testListId="8c84fa94-04c1-424b-9868-57a2d4851a1d" relativeResultsDirectory="1934ec9b-2319-458f-b8ec-90db595efd44">
      <Output>
        <StdOut>Given this is test case "CVV with special chars"
API Base URL: http://localhost:7135
Running test case: CVV with special chars
-&gt; done: CreditCardValidationSteps.GivenThisIsTestCase("CVV with special ...") (0.0s)
And I prepare a credit card with:
  --- table step argument ---
  | Owner    | Number           | Cvv  | IssueDate |
  | Jane Doe | 4111111111111111 | 12@# | 12/30     |
-&gt; done: CreditCardValidationSteps.GivenIPrepareACreditCardWith(&lt;table&gt;) (0.0s)
When I send the card to the validation API
-&gt; done: CreditCardValidationSteps.WhenISendTheCardToTheValidationAPI() (0.0s)
Then the response status should be 400
-&gt; error: Exception has been thrown by the target of an invocation. (0.0s)
And the response body should contain "Cvv"
-&gt; skipped because of previous errors
-&gt; duration: Scenario: Validate Credit Card: 20.8ms</StdOut>
        <ErrorInfo>
          <Message>  Expected HTTP 400, but got 0. Response body: 
Assert.That(actualStatus, Is.EqualTo(expectedStatus))
  Expected: 400
  But was:  0
</Message>
          <StackTrace>   at CardValidation.Tests.Steps.CreditCardValidationSteps.__a$_around_ThenTheResponseStatusShouldBe_100663316_o(Int32 expectedStatus) in /app/CardValidation.Tests/Steps/CreditCardValidationSteps.cs:line 88
   at CardValidation.Tests.Steps.CreditCardValidationSteps.__a$_around_ThenTheResponseStatusShouldBe_100663316_u(Object[])
   at Allure.Net.Commons.Steps.AllureAbstractStepAspect.WrapSyncVoid(Func`2 target, Object[] args, MethodBase metadata, String stepName, List`1 stepParameters)
   at InvokeStub_AllureAbstractStepAspect.WrapSyncVoid(Object, Span`1)

1)    at CardValidation.Tests.Steps.CreditCardValidationSteps.__a$_around_ThenTheResponseStatusShouldBe_100663316_o(Int32 expectedStatus) in /app/CardValidation.Tests/Steps/CreditCardValidationSteps.cs:line 88
   at CardValidation.Tests.Steps.CreditCardValidationSteps.__a$_around_ThenTheResponseStatusShouldBe_100663316_u(Object[])
   at Allure.Net.Commons.Steps.AllureAbstractStepAspect.WrapSyncVoid(Func`2 target, Object[] args, MethodBase metadata, String stepName, List`1 stepParameters)
   at InvokeStub_AllureAbstractStepAspect.WrapSyncVoid(Object, Span`1)

</StackTrace>
        </ErrorInfo>
      </Output>
    </UnitTestResult>
    <UnitTestResult executionId="20279186-7f4c-4207-8e18-d5e713f7d2a2" testId="cff6bf2e-27b0-590e-ddb7-07789e0e8b71" testName="ValidateCreditCard(&quot;Missing Number&quot;,&quot;Jane Doe&quot;,&quot;&quot;,&quot;123&quot;,&quot;12/30&quot;,&quot;400&quot;,&quot;Number&quot;,null)" computerName="docker-desktop" duration="00:00:00.0147280" startTime="2025-06-14T15:27:49.8859256+00:00" endTime="2025-06-14T15:27:49.9006528+00:00" testType="13cdc9d9-ddb5-4fa4-a97d-d965ccfc6d4b" outcome="Failed" testListId="8c84fa94-04c1-424b-9868-57a2d4851a1d" relativeResultsDirectory="20279186-7f4c-4207-8e18-d5e713f7d2a2">
      <Output>
        <StdOut>Given this is test case "Missing Number"
API Base URL: http://localhost:7135
Running test case: Missing Number
-&gt; done: CreditCardValidationSteps.GivenThisIsTestCase("Missing Number") (0.0s)
And I prepare a credit card with:
  --- table step argument ---
  | Owner    | Number | Cvv | IssueDate |
  | Jane Doe |        | 123 | 12/30     |
-&gt; done: CreditCardValidationSteps.GivenIPrepareACreditCardWith(&lt;table&gt;) (0.0s)
When I send the card to the validation API
-&gt; done: CreditCardValidationSteps.WhenISendTheCardToTheValidationAPI() (0.0s)
Then the response status should be 400
-&gt; error: Exception has been thrown by the target of an invocation. (0.0s)
And the response body should contain "Number"
-&gt; skipped because of previous errors
-&gt; duration: Scenario: Validate Credit Card: 12.5ms</StdOut>
        <ErrorInfo>
          <Message>  Expected HTTP 400, but got 0. Response body: 
Assert.That(actualStatus, Is.EqualTo(expectedStatus))
  Expected: 400
  But was:  0
</Message>
          <StackTrace>   at CardValidation.Tests.Steps.CreditCardValidationSteps.__a$_around_ThenTheResponseStatusShouldBe_100663316_o(Int32 expectedStatus) in /app/CardValidation.Tests/Steps/CreditCardValidationSteps.cs:line 88
   at CardValidation.Tests.Steps.CreditCardValidationSteps.__a$_around_ThenTheResponseStatusShouldBe_100663316_u(Object[])
   at Allure.Net.Commons.Steps.AllureAbstractStepAspect.WrapSyncVoid(Func`2 target, Object[] args, MethodBase metadata, String stepName, List`1 stepParameters)
   at InvokeStub_AllureAbstractStepAspect.WrapSyncVoid(Object, Span`1)

1)    at CardValidation.Tests.Steps.CreditCardValidationSteps.__a$_around_ThenTheResponseStatusShouldBe_100663316_o(Int32 expectedStatus) in /app/CardValidation.Tests/Steps/CreditCardValidationSteps.cs:line 88
   at CardValidation.Tests.Steps.CreditCardValidationSteps.__a$_around_ThenTheResponseStatusShouldBe_100663316_u(Object[])
   at Allure.Net.Commons.Steps.AllureAbstractStepAspect.WrapSyncVoid(Func`2 target, Object[] args, MethodBase metadata, String stepName, List`1 stepParameters)
   at InvokeStub_AllureAbstractStepAspect.WrapSyncVoid(Object, Span`1)

</StackTrace>
        </ErrorInfo>
      </Output>
    </UnitTestResult>
    <UnitTestResult executionId="cc36a5e1-c853-4c13-8217-4c0f0f98be4c" testId="11ed00b8-0216-ba7d-edf0-2178bbcf55bf" testName="ValidateCreditCard(&quot;Invalid CVV and Date Format&quot;,&quot;John Doe&quot;,&quot;4111111111111111&quot;,&quot;12&quot;,&quot;99-99&quot;,&quot;400&quot;,&quot;{\&quot;Cvv\&quot;:[\&quot;Wrong cvv\&quot;],\&quot;Date\&quot;:[\&quot;Wrong date\&quot;]}&quot;,null)" computerName="docker-desktop" duration="00:00:00.0193340" startTime="2025-06-14T15:27:50.0708934+00:00" endTime="2025-06-14T15:27:50.0902273+00:00" testType="13cdc9d9-ddb5-4fa4-a97d-d965ccfc6d4b" outcome="Failed" testListId="8c84fa94-04c1-424b-9868-57a2d4851a1d" relativeResultsDirectory="cc36a5e1-c853-4c13-8217-4c0f0f98be4c">
      <Output>
        <StdOut>Given this is test case "Invalid CVV and Date Format"
API Base URL: http://localhost:7135
Running test case: Invalid CVV and Date Format
-&gt; done: CreditCardValidationSteps.GivenThisIsTestCase("Invalid CVV and D...") (0.0s)
And I prepare a credit card with:
  --- table step argument ---
  | Owner    | Number           | Cvv | IssueDate |
  | John Doe | 4111111111111111 | 12  | 99-99     |
-&gt; done: CreditCardValidationSteps.GivenIPrepareACreditCardWith(&lt;table&gt;) (0.0s)
When I send the card to the validation API
-&gt; done: CreditCardValidationSteps.WhenISendTheCardToTheValidationAPI() (0.0s)
Then the response status should be 400
-&gt; error: Exception has been thrown by the target of an invocation. (0.0s)
And the response body should contain "{"Cvv":["Wrong cvv"],"Date":["Wrong date"]}"
-&gt; skipped because of previous errors
-&gt; duration: Scenario: Validate Credit Card: 16.4ms</StdOut>
        <ErrorInfo>
          <Message>  Expected HTTP 400, but got 0. Response body: 
Assert.That(actualStatus, Is.EqualTo(expectedStatus))
  Expected: 400
  But was:  0
</Message>
          <StackTrace>   at CardValidation.Tests.Steps.CreditCardValidationSteps.__a$_around_ThenTheResponseStatusShouldBe_100663316_o(Int32 expectedStatus) in /app/CardValidation.Tests/Steps/CreditCardValidationSteps.cs:line 88
   at CardValidation.Tests.Steps.CreditCardValidationSteps.__a$_around_ThenTheResponseStatusShouldBe_100663316_u(Object[])
   at Allure.Net.Commons.Steps.AllureAbstractStepAspect.WrapSyncVoid(Func`2 target, Object[] args, MethodBase metadata, String stepName, List`1 stepParameters)
   at InvokeStub_AllureAbstractStepAspect.WrapSyncVoid(Object, Span`1)

1)    at CardValidation.Tests.Steps.CreditCardValidationSteps.__a$_around_ThenTheResponseStatusShouldBe_100663316_o(Int32 expectedStatus) in /app/CardValidation.Tests/Steps/CreditCardValidationSteps.cs:line 88
   at CardValidation.Tests.Steps.CreditCardValidationSteps.__a$_around_ThenTheResponseStatusShouldBe_100663316_u(Object[])
   at Allure.Net.Commons.Steps.AllureAbstractStepAspect.WrapSyncVoid(Func`2 target, Object[] args, MethodBase metadata, String stepName, List`1 stepParameters)
   at InvokeStub_AllureAbstractStepAspect.WrapSyncVoid(Object, Span`1)

</StackTrace>
        </ErrorInfo>
      </Output>
    </UnitTestResult>
    <UnitTestResult executionId="62267bad-1d56-4130-b6fc-b92e9a3877e3" testId="16ef8a9a-364c-abcb-4047-0aefd08a7ca3" testName="ValidateCreditCard(&quot;Valid Visa Card&quot;,&quot;John Doe&quot;,&quot;4111111111111111&quot;,&quot;123&quot;,&quot;12/30&quot;,&quot;200&quot;,&quot;10&quot;,null)" computerName="docker-desktop" duration="00:00:00.2103060" startTime="2025-06-14T15:27:49.6178562+00:00" endTime="2025-06-14T15:27:49.8281163+00:00" testType="13cdc9d9-ddb5-4fa4-a97d-d965ccfc6d4b" outcome="Failed" testListId="8c84fa94-04c1-424b-9868-57a2d4851a1d" relativeResultsDirectory="62267bad-1d56-4130-b6fc-b92e9a3877e3">
      <Output>
        <StdOut>Given this is test case "Valid Visa Card"
API Base URL: http://localhost:7135
Running test case: Valid Visa Card
-&gt; done: CreditCardValidationSteps.GivenThisIsTestCase("Valid Visa Card") (0.0s)
And I prepare a credit card with:
  --- table step argument ---
  | Owner    | Number           | Cvv | IssueDate |
  | John Doe | 4111111111111111 | 123 | 12/30     |
-&gt; done: CreditCardValidationSteps.GivenIPrepareACreditCardWith(&lt;table&gt;) (0.0s)
When I send the card to the validation API
-&gt; done: CreditCardValidationSteps.WhenISendTheCardToTheValidationAPI() (0.0s)
Then the response status should be 200
-&gt; error: Exception has been thrown by the target of an invocation. (0.0s)
And the response body should contain "10"
-&gt; skipped because of previous errors
-&gt; duration: Scenario: Validate Credit Card: 163.6ms</StdOut>
        <ErrorInfo>
          <Message>  Expected HTTP 200, but got 0. Response body: 
Assert.That(actualStatus, Is.EqualTo(expectedStatus))
  Expected: 200
  But was:  0
</Message>
          <StackTrace>   at CardValidation.Tests.Steps.CreditCardValidationSteps.__a$_around_ThenTheResponseStatusShouldBe_100663316_o(Int32 expectedStatus) in /app/CardValidation.Tests/Steps/CreditCardValidationSteps.cs:line 88
   at CardValidation.Tests.Steps.CreditCardValidationSteps.__a$_around_ThenTheResponseStatusShouldBe_100663316_u(Object[])
   at Allure.Net.Commons.Steps.AllureAbstractStepAspect.WrapSyncVoid(Func`2 target, Object[] args, MethodBase metadata, String stepName, List`1 stepParameters)
   at InvokeStub_AllureAbstractStepAspect.WrapSyncVoid(Object, Span`1)

1)    at CardValidation.Tests.Steps.CreditCardValidationSteps.__a$_around_ThenTheResponseStatusShouldBe_100663316_o(Int32 expectedStatus) in /app/CardValidation.Tests/Steps/CreditCardValidationSteps.cs:line 88
   at CardValidation.Tests.Steps.CreditCardValidationSteps.__a$_around_ThenTheResponseStatusShouldBe_100663316_u(Object[])
   at Allure.Net.Commons.Steps.AllureAbstractStepAspect.WrapSyncVoid(Func`2 target, Object[] args, MethodBase metadata, String stepName, List`1 stepParameters)
   at InvokeStub_AllureAbstractStepAspect.WrapSyncVoid(Object, Span`1)

</StackTrace>
        </ErrorInfo>
      </Output>
    </UnitTestResult>
    <UnitTestResult executionId="c53c8890-e03a-4571-9054-9d4a11f511f1" testId="ffd94f97-d161-5272-fc39-103757df0158" testName="ValidateCreditCard(&quot;Card Number with spaces&quot;,&quot;John Doe&quot;,&quot;4111 1111 1111 1111&quot;,&quot;123&quot;,&quot;12/30&quot;,&quot;400&quot;,&quot;Number&quot;,null)" computerName="docker-desktop" duration="00:00:00.0162269" startTime="2025-06-14T15:27:50.0546198+00:00" endTime="2025-06-14T15:27:50.0708470+00:00" testType="13cdc9d9-ddb5-4fa4-a97d-d965ccfc6d4b" outcome="Failed" testListId="8c84fa94-04c1-424b-9868-57a2d4851a1d" relativeResultsDirectory="c53c8890-e03a-4571-9054-9d4a11f511f1">
      <Output>
        <StdOut>Given this is test case "Card Number with spaces"
API Base URL: http://localhost:7135
Running test case: Card Number with spaces
-&gt; done: CreditCardValidationSteps.GivenThisIsTestCase("Card Number with ...") (0.0s)
And I prepare a credit card with:
  --- table step argument ---
  | Owner    | Number              | Cvv | IssueDate |
  | John Doe | 4111 1111 1111 1111 | 123 | 12/30     |
-&gt; done: CreditCardValidationSteps.GivenIPrepareACreditCardWith(&lt;table&gt;) (0.0s)
When I send the card to the validation API
-&gt; done: CreditCardValidationSteps.WhenISendTheCardToTheValidationAPI() (0.0s)
Then the response status should be 400
-&gt; error: Exception has been thrown by the target of an invocation. (0.0s)
And the response body should contain "Number"
-&gt; skipped because of previous errors
-&gt; duration: Scenario: Validate Credit Card: 13.4ms</StdOut>
        <ErrorInfo>
          <Message>  Expected HTTP 400, but got 0. Response body: 
Assert.That(actualStatus, Is.EqualTo(expectedStatus))
  Expected: 400
  But was:  0
</Message>
          <StackTrace>   at CardValidation.Tests.Steps.CreditCardValidationSteps.__a$_around_ThenTheResponseStatusShouldBe_100663316_o(Int32 expectedStatus) in /app/CardValidation.Tests/Steps/CreditCardValidationSteps.cs:line 88
   at CardValidation.Tests.Steps.CreditCardValidationSteps.__a$_around_ThenTheResponseStatusShouldBe_100663316_u(Object[])
   at Allure.Net.Commons.Steps.AllureAbstractStepAspect.WrapSyncVoid(Func`2 target, Object[] args, MethodBase metadata, String stepName, List`1 stepParameters)
   at InvokeStub_AllureAbstractStepAspect.WrapSyncVoid(Object, Span`1)

1)    at CardValidation.Tests.Steps.CreditCardValidationSteps.__a$_around_ThenTheResponseStatusShouldBe_100663316_o(Int32 expectedStatus) in /app/CardValidation.Tests/Steps/CreditCardValidationSteps.cs:line 88
   at CardValidation.Tests.Steps.CreditCardValidationSteps.__a$_around_ThenTheResponseStatusShouldBe_100663316_u(Object[])
   at Allure.Net.Commons.Steps.AllureAbstractStepAspect.WrapSyncVoid(Func`2 target, Object[] args, MethodBase metadata, String stepName, List`1 stepParameters)
   at InvokeStub_AllureAbstractStepAspect.WrapSyncVoid(Object, Span`1)

</StackTrace>
        </ErrorInfo>
      </Output>
    </UnitTestResult>
    <UnitTestResult executionId="79c1750e-37d1-4f4e-bb5e-a423fc6a62e3" testId="68fac506-8cbd-2307-ddcc-118d3c5c55c2" testName="ValidateCreditCard(&quot;Expired Card Past Date&quot;,&quot;Expired User&quot;,&quot;4111111111111111&quot;,&quot;123&quot;,&quot;01/21&quot;,&quot;400&quot;,&quot;date&quot;,null)" computerName="docker-desktop" duration="00:00:00.0249130" startTime="2025-06-14T15:27:49.9709763+00:00" endTime="2025-06-14T15:27:49.9958886+00:00" testType="13cdc9d9-ddb5-4fa4-a97d-d965ccfc6d4b" outcome="Failed" testListId="8c84fa94-04c1-424b-9868-57a2d4851a1d" relativeResultsDirectory="79c1750e-37d1-4f4e-bb5e-a423fc6a62e3">
      <Output>
        <StdOut>Given this is test case "Expired Card Past Date"
API Base URL: http://localhost:7135
Running test case: Expired Card Past Date
-&gt; done: CreditCardValidationSteps.GivenThisIsTestCase("Expired Card Past...") (0.0s)
And I prepare a credit card with:
  --- table step argument ---
  | Owner        | Number           | Cvv | IssueDate |
  | Expired User | 4111111111111111 | 123 | 01/21     |
-&gt; done: CreditCardValidationSteps.GivenIPrepareACreditCardWith(&lt;table&gt;) (0.0s)
When I send the card to the validation API
-&gt; done: CreditCardValidationSteps.WhenISendTheCardToTheValidationAPI() (0.0s)
Then the response status should be 400
-&gt; error: Exception has been thrown by the target of an invocation. (0.0s)
And the response body should contain "date"
-&gt; skipped because of previous errors
-&gt; duration: Scenario: Validate Credit Card: 22.3ms</StdOut>
        <ErrorInfo>
          <Message>  Expected HTTP 400, but got 0. Response body: 
Assert.That(actualStatus, Is.EqualTo(expectedStatus))
  Expected: 400
  But was:  0
</Message>
          <StackTrace>   at CardValidation.Tests.Steps.CreditCardValidationSteps.__a$_around_ThenTheResponseStatusShouldBe_100663316_o(Int32 expectedStatus) in /app/CardValidation.Tests/Steps/CreditCardValidationSteps.cs:line 88
   at CardValidation.Tests.Steps.CreditCardValidationSteps.__a$_around_ThenTheResponseStatusShouldBe_100663316_u(Object[])
   at Allure.Net.Commons.Steps.AllureAbstractStepAspect.WrapSyncVoid(Func`2 target, Object[] args, MethodBase metadata, String stepName, List`1 stepParameters)
   at InvokeStub_AllureAbstractStepAspect.WrapSyncVoid(Object, Span`1)

1)    at CardValidation.Tests.Steps.CreditCardValidationSteps.__a$_around_ThenTheResponseStatusShouldBe_100663316_o(Int32 expectedStatus) in /app/CardValidation.Tests/Steps/CreditCardValidationSteps.cs:line 88
   at CardValidation.Tests.Steps.CreditCardValidationSteps.__a$_around_ThenTheResponseStatusShouldBe_100663316_u(Object[])
   at Allure.Net.Commons.Steps.AllureAbstractStepAspect.WrapSyncVoid(Func`2 target, Object[] args, MethodBase metadata, String stepName, List`1 stepParameters)
   at InvokeStub_AllureAbstractStepAspect.WrapSyncVoid(Object, Span`1)

</StackTrace>
        </ErrorInfo>
      </Output>
    </UnitTestResult>
    <UnitTestResult executionId="ef576f4c-2f5f-4122-9fb2-ec09726940de" testId="78ff0762-a7af-0539-6b89-66a2e6a30f45" testName="ValidateCreditCard(&quot;Invalid Card Number&quot;,&quot;Test User&quot;,&quot;1234567890123456&quot;,&quot;123&quot;,&quot;12/30&quot;,&quot;400&quot;,&quot;Number&quot;,null)" computerName="docker-desktop" duration="00:00:00.0164280" startTime="2025-06-14T15:27:49.9367537+00:00" endTime="2025-06-14T15:27:49.9531816+00:00" testType="13cdc9d9-ddb5-4fa4-a97d-d965ccfc6d4b" outcome="Failed" testListId="8c84fa94-04c1-424b-9868-57a2d4851a1d" relativeResultsDirectory="ef576f4c-2f5f-4122-9fb2-ec09726940de">
      <Output>
        <StdOut>Given this is test case "Invalid Card Number"
API Base URL: http://localhost:7135
Running test case: Invalid Card Number
-&gt; done: CreditCardValidationSteps.GivenThisIsTestCase("Invalid Card Number") (0.0s)
And I prepare a credit card with:
  --- table step argument ---
  | Owner     | Number           | Cvv | IssueDate |
  | Test User | 1234567890123456 | 123 | 12/30     |
-&gt; done: CreditCardValidationSteps.GivenIPrepareACreditCardWith(&lt;table&gt;) (0.0s)
When I send the card to the validation API
-&gt; done: CreditCardValidationSteps.WhenISendTheCardToTheValidationAPI() (0.0s)
Then the response status should be 400
-&gt; error: Exception has been thrown by the target of an invocation. (0.0s)
And the response body should contain "Number"
-&gt; skipped because of previous errors
-&gt; duration: Scenario: Validate Credit Card: 14.1ms</StdOut>
        <ErrorInfo>
          <Message>  Expected HTTP 400, but got 0. Response body: 
Assert.That(actualStatus, Is.EqualTo(expectedStatus))
  Expected: 400
  But was:  0
</Message>
          <StackTrace>   at CardValidation.Tests.Steps.CreditCardValidationSteps.__a$_around_ThenTheResponseStatusShouldBe_100663316_o(Int32 expectedStatus) in /app/CardValidation.Tests/Steps/CreditCardValidationSteps.cs:line 88
   at CardValidation.Tests.Steps.CreditCardValidationSteps.__a$_around_ThenTheResponseStatusShouldBe_100663316_u(Object[])
   at Allure.Net.Commons.Steps.AllureAbstractStepAspect.WrapSyncVoid(Func`2 target, Object[] args, MethodBase metadata, String stepName, List`1 stepParameters)
   at InvokeStub_AllureAbstractStepAspect.WrapSyncVoid(Object, Span`1)

1)    at CardValidation.Tests.Steps.CreditCardValidationSteps.__a$_around_ThenTheResponseStatusShouldBe_100663316_o(Int32 expectedStatus) in /app/CardValidation.Tests/Steps/CreditCardValidationSteps.cs:line 88
   at CardValidation.Tests.Steps.CreditCardValidationSteps.__a$_around_ThenTheResponseStatusShouldBe_100663316_u(Object[])
   at Allure.Net.Commons.Steps.AllureAbstractStepAspect.WrapSyncVoid(Func`2 target, Object[] args, MethodBase metadata, String stepName, List`1 stepParameters)
   at InvokeStub_AllureAbstractStepAspect.WrapSyncVoid(Object, Span`1)

</StackTrace>
        </ErrorInfo>
      </Output>
    </UnitTestResult>
    <UnitTestResult executionId="69e261b9-92c8-4124-82ec-02080131f6eb" testId="b09f81a2-1945-73ea-e99d-fd5cb5d54e77" testName="ValidateCreditCard(&quot;Valid American Express&quot;,&quot;Bob Johnson&quot;,&quot;378282246310005&quot;,&quot;1234&quot;,&quot;06/28&quot;,&quot;200&quot;,&quot;30&quot;,null)" computerName="docker-desktop" duration="00:00:00.0147960" startTime="2025-06-14T15:27:49.8526636+00:00" endTime="2025-06-14T15:27:49.8674593+00:00" testType="13cdc9d9-ddb5-4fa4-a97d-d965ccfc6d4b" outcome="Failed" testListId="8c84fa94-04c1-424b-9868-57a2d4851a1d" relativeResultsDirectory="69e261b9-92c8-4124-82ec-02080131f6eb">
      <Output>
        <StdOut>Given this is test case "Valid American Express"
API Base URL: http://localhost:7135
Running test case: Valid American Express
-&gt; done: CreditCardValidationSteps.GivenThisIsTestCase("Valid American Ex...") (0.0s)
And I prepare a credit card with:
  --- table step argument ---
  | Owner       | Number          | Cvv  | IssueDate |
  | Bob Johnson | 378282246310005 | 1234 | 06/28     |
-&gt; done: CreditCardValidationSteps.GivenIPrepareACreditCardWith(&lt;table&gt;) (0.0s)
When I send the card to the validation API
-&gt; done: CreditCardValidationSteps.WhenISendTheCardToTheValidationAPI() (0.0s)
Then the response status should be 200
-&gt; error: Exception has been thrown by the target of an invocation. (0.0s)
And the response body should contain "30"
-&gt; skipped because of previous errors
-&gt; duration: Scenario: Validate Credit Card: 12.4ms</StdOut>
        <ErrorInfo>
          <Message>  Expected HTTP 200, but got 0. Response body: 
Assert.That(actualStatus, Is.EqualTo(expectedStatus))
  Expected: 200
  But was:  0
</Message>
          <StackTrace>   at CardValidation.Tests.Steps.CreditCardValidationSteps.__a$_around_ThenTheResponseStatusShouldBe_100663316_o(Int32 expectedStatus) in /app/CardValidation.Tests/Steps/CreditCardValidationSteps.cs:line 88
   at CardValidation.Tests.Steps.CreditCardValidationSteps.__a$_around_ThenTheResponseStatusShouldBe_100663316_u(Object[])
   at Allure.Net.Commons.Steps.AllureAbstractStepAspect.WrapSyncVoid(Func`2 target, Object[] args, MethodBase metadata, String stepName, List`1 stepParameters)
   at InvokeStub_AllureAbstractStepAspect.WrapSyncVoid(Object, Span`1)

1)    at CardValidation.Tests.Steps.CreditCardValidationSteps.__a$_around_ThenTheResponseStatusShouldBe_100663316_o(Int32 expectedStatus) in /app/CardValidation.Tests/Steps/CreditCardValidationSteps.cs:line 88
   at CardValidation.Tests.Steps.CreditCardValidationSteps.__a$_around_ThenTheResponseStatusShouldBe_100663316_u(Object[])
   at Allure.Net.Commons.Steps.AllureAbstractStepAspect.WrapSyncVoid(Func`2 target, Object[] args, MethodBase metadata, String stepName, List`1 stepParameters)
   at InvokeStub_AllureAbstractStepAspect.WrapSyncVoid(Object, Span`1)

</StackTrace>
        </ErrorInfo>
      </Output>
    </UnitTestResult>
    <UnitTestResult executionId="929e7eca-9eee-46ff-bb81-eaf357d3f200" testId="adf1ce10-4987-1f88-3692-e055f2ea7ce7" testName="ValidateCreditCard(&quot;Invalid All Fields&quot;,&quot;&quot;,&quot;123456&quot;,&quot;abc&quot;,&quot;invalid&quot;,&quot;400&quot;,&quot;{\&quot;Cvv\&quot;:[\&quot;Wrong cvv\&quot;],\&quot;Date\&quot;:[\&quot;Wrong date\&quot;],\&quot;Owner\&quot;:[\&quot;Owner is required\&quot;],\&quot;Number\&quot;:[\&quot;Wrong number\&quot;]}&quot;,null)" computerName="docker-desktop" duration="00:00:00.0217660" startTime="2025-06-14T15:27:50.1088890+00:00" endTime="2025-06-14T15:27:50.1306549+00:00" testType="13cdc9d9-ddb5-4fa4-a97d-d965ccfc6d4b" outcome="Failed" testListId="8c84fa94-04c1-424b-9868-57a2d4851a1d" relativeResultsDirectory="929e7eca-9eee-46ff-bb81-eaf357d3f200">
      <Output>
        <StdOut>Given this is test case "Invalid All Fields"
API Base URL: http://localhost:7135
Running test case: Invalid All Fields
-&gt; done: CreditCardValidationSteps.GivenThisIsTestCase("Invalid All Fields") (0.0s)
And I prepare a credit card with:
  --- table step argument ---
  | Owner | Number | Cvv | IssueDate |
  |       | 123456 | abc | invalid   |
-&gt; done: CreditCardValidationSteps.GivenIPrepareACreditCardWith(&lt;table&gt;) (0.0s)
When I send the card to the validation API
-&gt; done: CreditCardValidationSteps.WhenISendTheCardToTheValidationAPI() (0.0s)
Then the response status should be 400
-&gt; error: Exception has been thrown by the target of an invocation. (0.0s)
And the response body should contain "{"Cvv":["Wrong cvv"],"Date":["Wrong date"],"Owner":["Owner is required"],"Number":["Wrong number"]}"
-&gt; skipped because of previous errors
-&gt; duration: Scenario: Validate Credit Card: 18.7ms</StdOut>
        <ErrorInfo>
          <Message>  Expected HTTP 400, but got 0. Response body: 
Assert.That(actualStatus, Is.EqualTo(expectedStatus))
  Expected: 400
  But was:  0
</Message>
          <StackTrace>   at CardValidation.Tests.Steps.CreditCardValidationSteps.__a$_around_ThenTheResponseStatusShouldBe_100663316_o(Int32 expectedStatus) in /app/CardValidation.Tests/Steps/CreditCardValidationSteps.cs:line 88
   at CardValidation.Tests.Steps.CreditCardValidationSteps.__a$_around_ThenTheResponseStatusShouldBe_100663316_u(Object[])
   at Allure.Net.Commons.Steps.AllureAbstractStepAspect.WrapSyncVoid(Func`2 target, Object[] args, MethodBase metadata, String stepName, List`1 stepParameters)
   at InvokeStub_AllureAbstractStepAspect.WrapSyncVoid(Object, Span`1)

1)    at CardValidation.Tests.Steps.CreditCardValidationSteps.__a$_around_ThenTheResponseStatusShouldBe_100663316_o(Int32 expectedStatus) in /app/CardValidation.Tests/Steps/CreditCardValidationSteps.cs:line 88
   at CardValidation.Tests.Steps.CreditCardValidationSteps.__a$_around_ThenTheResponseStatusShouldBe_100663316_u(Object[])
   at Allure.Net.Commons.Steps.AllureAbstractStepAspect.WrapSyncVoid(Func`2 target, Object[] args, MethodBase metadata, String stepName, List`1 stepParameters)
   at InvokeStub_AllureAbstractStepAspect.WrapSyncVoid(Object, Span`1)

</StackTrace>
        </ErrorInfo>
      </Output>
    </UnitTestResult>
    <UnitTestResult executionId="6ee5c358-d7fb-4515-b155-8dd8c4e0b9b2" testId="1612b095-0679-bcfa-710a-560bf15c9807" testName="ValidateCreditCard(&quot;Valid MasterCard&quot;,&quot;Alice Smith&quot;,&quot;5555555555554444&quot;,&quot;321&quot;,&quot;11/29&quot;,&quot;200&quot;,&quot;20&quot;,null)" computerName="docker-desktop" duration="00:00:00.0235440" startTime="2025-06-14T15:27:49.8290654+00:00" endTime="2025-06-14T15:27:49.8526095+00:00" testType="13cdc9d9-ddb5-4fa4-a97d-d965ccfc6d4b" outcome="Failed" testListId="8c84fa94-04c1-424b-9868-57a2d4851a1d" relativeResultsDirectory="6ee5c358-d7fb-4515-b155-8dd8c4e0b9b2">
      <Output>
        <StdOut>Given this is test case "Valid MasterCard"
API Base URL: http://localhost:7135
Running test case: Valid MasterCard
-&gt; done: CreditCardValidationSteps.GivenThisIsTestCase("Valid MasterCard") (0.0s)
And I prepare a credit card with:
  --- table step argument ---
  | Owner       | Number           | Cvv | IssueDate |
  | Alice Smith | 5555555555554444 | 321 | 11/29     |
-&gt; done: CreditCardValidationSteps.GivenIPrepareACreditCardWith(&lt;table&gt;) (0.0s)
When I send the card to the validation API
-&gt; done: CreditCardValidationSteps.WhenISendTheCardToTheValidationAPI() (0.0s)
Then the response status should be 200
-&gt; error: Exception has been thrown by the target of an invocation. (0.0s)
And the response body should contain "20"
-&gt; skipped because of previous errors
-&gt; duration: Scenario: Validate Credit Card: 14.5ms</StdOut>
        <ErrorInfo>
          <Message>  Expected HTTP 200, but got 0. Response body: 
Assert.That(actualStatus, Is.EqualTo(expectedStatus))
  Expected: 200
  But was:  0
</Message>
          <StackTrace>   at CardValidation.Tests.Steps.CreditCardValidationSteps.__a$_around_ThenTheResponseStatusShouldBe_100663316_o(Int32 expectedStatus) in /app/CardValidation.Tests/Steps/CreditCardValidationSteps.cs:line 88
   at CardValidation.Tests.Steps.CreditCardValidationSteps.__a$_around_ThenTheResponseStatusShouldBe_100663316_u(Object[])
   at Allure.Net.Commons.Steps.AllureAbstractStepAspect.WrapSyncVoid(Func`2 target, Object[] args, MethodBase metadata, String stepName, List`1 stepParameters)
   at InvokeStub_AllureAbstractStepAspect.WrapSyncVoid(Object, Span`1)

1)    at CardValidation.Tests.Steps.CreditCardValidationSteps.__a$_around_ThenTheResponseStatusShouldBe_100663316_o(Int32 expectedStatus) in /app/CardValidation.Tests/Steps/CreditCardValidationSteps.cs:line 88
   at CardValidation.Tests.Steps.CreditCardValidationSteps.__a$_around_ThenTheResponseStatusShouldBe_100663316_u(Object[])
   at Allure.Net.Commons.Steps.AllureAbstractStepAspect.WrapSyncVoid(Func`2 target, Object[] args, MethodBase metadata, String stepName, List`1 stepParameters)
   at InvokeStub_AllureAbstractStepAspect.WrapSyncVoid(Object, Span`1)

</StackTrace>
        </ErrorInfo>
      </Output>
    </UnitTestResult>
  </Results>
  <TestDefinitions>
    <UnitTest name="ValidateCreditCard(&quot;Valid American Express&quot;,&quot;Bob Johnson&quot;,&quot;378282246310005&quot;,&quot;1234&quot;,&quot;06/28&quot;,&quot;200&quot;,&quot;30&quot;,null)" storage="/app/cardvalidation.tests/bin/debug/net8.0/cardvalidation.tests.dll" id="b09f81a2-1945-73ea-e99d-fd5cb5d54e77">
      <Execution id="69e261b9-92c8-4124-82ec-02080131f6eb" />
      <TestMethod codeBase="/app/CardValidation.Tests/bin/Debug/net8.0/CardValidation.Tests.dll" adapterTypeName="executor://nunit3testexecutor/" className="CardValidation.Tests.Features.CreditCardValidationAPIFeature" name="ValidateCreditCard(&quot;Valid American Express&quot;,&quot;Bob Johnson&quot;,&quot;378282246310005&quot;,&quot;1234&quot;,&quot;06/28&quot;,&quot;200&quot;,&quot;30&quot;,null)" />
    </UnitTest>
    <UnitTest name="ValidateCreditCard(&quot;Missing CVV&quot;,&quot;Jane Doe&quot;,&quot;4111111111111111&quot;,&quot;&quot;,&quot;12/30&quot;,&quot;400&quot;,&quot;Cvv&quot;,null)" storage="/app/cardvalidation.tests/bin/debug/net8.0/cardvalidation.tests.dll" id="20dc1195-9c36-e5e4-a77d-cef27585349b">
      <Execution id="b142d5de-7721-42c3-b6ed-18240813de3f" />
      <TestMethod codeBase="/app/CardValidation.Tests/bin/Debug/net8.0/CardValidation.Tests.dll" adapterTypeName="executor://nunit3testexecutor/" className="CardValidation.Tests.Features.CreditCardValidationAPIFeature" name="ValidateCreditCard(&quot;Missing CVV&quot;,&quot;Jane Doe&quot;,&quot;4111111111111111&quot;,&quot;&quot;,&quot;12/30&quot;,&quot;400&quot;,&quot;Cvv&quot;,null)" />
    </UnitTest>
    <UnitTest name="ValidateCreditCard(&quot;Invalid All Fields&quot;,&quot;&quot;,&quot;123456&quot;,&quot;abc&quot;,&quot;invalid&quot;,&quot;400&quot;,&quot;{\&quot;Cvv\&quot;:[\&quot;Wrong cvv\&quot;],\&quot;Date\&quot;:[\&quot;Wrong date\&quot;],\&quot;Owner\&quot;:[\&quot;Owner is required\&quot;],\&quot;Number\&quot;:[\&quot;Wrong number\&quot;]}&quot;,null)" storage="/app/cardvalidation.tests/bin/debug/net8.0/cardvalidation.tests.dll" id="adf1ce10-4987-1f88-3692-e055f2ea7ce7">
      <Execution id="929e7eca-9eee-46ff-bb81-eaf357d3f200" />
      <TestMethod codeBase="/app/CardValidation.Tests/bin/Debug/net8.0/CardValidation.Tests.dll" adapterTypeName="executor://nunit3testexecutor/" className="CardValidation.Tests.Features.CreditCardValidationAPIFeature" name="ValidateCreditCard(&quot;Invalid All Fields&quot;,&quot;&quot;,&quot;123456&quot;,&quot;abc&quot;,&quot;invalid&quot;,&quot;400&quot;,&quot;{\&quot;Cvv\&quot;:[\&quot;Wrong cvv\&quot;],\&quot;Date\&quot;:[\&quot;Wrong date\&quot;],\&quot;Owner\&quot;:[\&quot;Owner is required\&quot;],\&quot;Number\&quot;:[\&quot;Wrong number\&quot;]}&quot;,null)" />
    </UnitTest>
    <UnitTest name="ValidateCreditCard(&quot;Invalid Owner and CVV&quot;,&quot;John 123&quot;,&quot;4111111111111111&quot;,&quot;12&quot;,&quot;12/30&quot;,&quot;400&quot;,&quot;{\&quot;Cvv\&quot;:[\&quot;Wrong cvv\&quot;],\&quot;Owner\&quot;:[\&quot;Wrong owner\&quot;]}&quot;,null)" storage="/app/cardvalidation.tests/bin/debug/net8.0/cardvalidation.tests.dll" id="470e68ea-e419-d394-555b-a31ecfd65e61">
      <Execution id="9fbecdf1-666d-4932-9433-8e1c4d57130e" />
      <TestMethod codeBase="/app/CardValidation.Tests/bin/Debug/net8.0/CardValidation.Tests.dll" adapterTypeName="executor://nunit3testexecutor/" className="CardValidation.Tests.Features.CreditCardValidationAPIFeature" name="ValidateCreditCard(&quot;Invalid Owner and CVV&quot;,&quot;John 123&quot;,&quot;4111111111111111&quot;,&quot;12&quot;,&quot;12/30&quot;,&quot;400&quot;,&quot;{\&quot;Cvv\&quot;:[\&quot;Wrong cvv\&quot;],\&quot;Owner\&quot;:[\&quot;Wrong owner\&quot;]}&quot;,null)" />
    </UnitTest>
    <UnitTest name="ValidateCreditCard(&quot;Invalid CVV length Visa&quot;,&quot;Clara Wells&quot;,&quot;4111111111111111&quot;,&quot;12&quot;,&quot;12/30&quot;,&quot;400&quot;,&quot;Cvv&quot;,null)" storage="/app/cardvalidation.tests/bin/debug/net8.0/cardvalidation.tests.dll" id="63595178-fc82-5569-d94c-3932b3f89509">
      <Execution id="997a2069-1975-4861-b7c1-9d55ca740a91" />
      <TestMethod codeBase="/app/CardValidation.Tests/bin/Debug/net8.0/CardValidation.Tests.dll" adapterTypeName="executor://nunit3testexecutor/" className="CardValidation.Tests.Features.CreditCardValidationAPIFeature" name="ValidateCreditCard(&quot;Invalid CVV length Visa&quot;,&quot;Clara Wells&quot;,&quot;4111111111111111&quot;,&quot;12&quot;,&quot;12/30&quot;,&quot;400&quot;,&quot;Cvv&quot;,null)" />
    </UnitTest>
    <UnitTest name="ValidateCreditCard(&quot;Invalid CVV and Date Format&quot;,&quot;John Doe&quot;,&quot;4111111111111111&quot;,&quot;12&quot;,&quot;99-99&quot;,&quot;400&quot;,&quot;{\&quot;Cvv\&quot;:[\&quot;Wrong cvv\&quot;],\&quot;Date\&quot;:[\&quot;Wrong date\&quot;]}&quot;,null)" storage="/app/cardvalidation.tests/bin/debug/net8.0/cardvalidation.tests.dll" id="11ed00b8-0216-ba7d-edf0-2178bbcf55bf">
      <Execution id="cc36a5e1-c853-4c13-8217-4c0f0f98be4c" />
      <TestMethod codeBase="/app/CardValidation.Tests/bin/Debug/net8.0/CardValidation.Tests.dll" adapterTypeName="executor://nunit3testexecutor/" className="CardValidation.Tests.Features.CreditCardValidationAPIFeature" name="ValidateCreditCard(&quot;Invalid CVV and Date Format&quot;,&quot;John Doe&quot;,&quot;4111111111111111&quot;,&quot;12&quot;,&quot;99-99&quot;,&quot;400&quot;,&quot;{\&quot;Cvv\&quot;:[\&quot;Wrong cvv\&quot;],\&quot;Date\&quot;:[\&quot;Wrong date\&quot;]}&quot;,null)" />
    </UnitTest>
    <UnitTest name="ValidateCreditCard(&quot;Missing IssueDate&quot;,&quot;Jane Doe&quot;,&quot;4111111111111111&quot;,&quot;123&quot;,&quot;&quot;,&quot;400&quot;,&quot;date&quot;,null)" storage="/app/cardvalidation.tests/bin/debug/net8.0/cardvalidation.tests.dll" id="adc08fa8-fee9-a023-40ff-926214b51695">
      <Execution id="04275393-c4ba-451e-968a-fe69dbf59f6e" />
      <TestMethod codeBase="/app/CardValidation.Tests/bin/Debug/net8.0/CardValidation.Tests.dll" adapterTypeName="executor://nunit3testexecutor/" className="CardValidation.Tests.Features.CreditCardValidationAPIFeature" name="ValidateCreditCard(&quot;Missing IssueDate&quot;,&quot;Jane Doe&quot;,&quot;4111111111111111&quot;,&quot;123&quot;,&quot;&quot;,&quot;400&quot;,&quot;date&quot;,null)" />
    </UnitTest>
    <UnitTest name="ValidateCreditCard(&quot;Card Number with spaces&quot;,&quot;John Doe&quot;,&quot;4111 1111 1111 1111&quot;,&quot;123&quot;,&quot;12/30&quot;,&quot;400&quot;,&quot;Number&quot;,null)" storage="/app/cardvalidation.tests/bin/debug/net8.0/cardvalidation.tests.dll" id="ffd94f97-d161-5272-fc39-103757df0158">
      <Execution id="c53c8890-e03a-4571-9054-9d4a11f511f1" />
      <TestMethod codeBase="/app/CardValidation.Tests/bin/Debug/net8.0/CardValidation.Tests.dll" adapterTypeName="executor://nunit3testexecutor/" className="CardValidation.Tests.Features.CreditCardValidationAPIFeature" name="ValidateCreditCard(&quot;Card Number with spaces&quot;,&quot;John Doe&quot;,&quot;4111 1111 1111 1111&quot;,&quot;123&quot;,&quot;12/30&quot;,&quot;400&quot;,&quot;Number&quot;,null)" />
    </UnitTest>
    <UnitTest name="ValidateCreditCard(&quot;Owner Contains Card Number&quot;,&quot;John 4111111&quot;,&quot;4111111111111111&quot;,&quot;123&quot;,&quot;12/30&quot;,&quot;400&quot;,&quot;Owner&quot;,null)" storage="/app/cardvalidation.tests/bin/debug/net8.0/cardvalidation.tests.dll" id="59baaf00-14ab-9c15-2cf3-9c9f8aaf579c">
      <Execution id="85c17475-5bd8-4ffd-9321-967aee1449ff" />
      <TestMethod codeBase="/app/CardValidation.Tests/bin/Debug/net8.0/CardValidation.Tests.dll" adapterTypeName="executor://nunit3testexecutor/" className="CardValidation.Tests.Features.CreditCardValidationAPIFeature" name="ValidateCreditCard(&quot;Owner Contains Card Number&quot;,&quot;John 4111111&quot;,&quot;4111111111111111&quot;,&quot;123&quot;,&quot;12/30&quot;,&quot;400&quot;,&quot;Owner&quot;,null)" />
    </UnitTest>
    <UnitTest name="ValidateCreditCard(&quot;Missing Number&quot;,&quot;Jane Doe&quot;,&quot;&quot;,&quot;123&quot;,&quot;12/30&quot;,&quot;400&quot;,&quot;Number&quot;,null)" storage="/app/cardvalidation.tests/bin/debug/net8.0/cardvalidation.tests.dll" id="cff6bf2e-27b0-590e-ddb7-07789e0e8b71">
      <Execution id="20279186-7f4c-4207-8e18-d5e713f7d2a2" />
      <TestMethod codeBase="/app/CardValidation.Tests/bin/Debug/net8.0/CardValidation.Tests.dll" adapterTypeName="executor://nunit3testexecutor/" className="CardValidation.Tests.Features.CreditCardValidationAPIFeature" name="ValidateCreditCard(&quot;Missing Number&quot;,&quot;Jane Doe&quot;,&quot;&quot;,&quot;123&quot;,&quot;12/30&quot;,&quot;400&quot;,&quot;Number&quot;,null)" />
    </UnitTest>
    <UnitTest name="ValidateCreditCard(&quot;Missing Owner&quot;,&quot;&quot;,&quot;4111111111111111&quot;,&quot;123&quot;,&quot;12/30&quot;,&quot;400&quot;,&quot;Owner&quot;,null)" storage="/app/cardvalidation.tests/bin/debug/net8.0/cardvalidation.tests.dll" id="7b4e6a07-dd17-f5f2-ca6e-26619edc7e8c">
      <Execution id="67c27c6f-0e64-4220-acba-922a6b46bf3c" />
      <TestMethod codeBase="/app/CardValidation.Tests/bin/Debug/net8.0/CardValidation.Tests.dll" adapterTypeName="executor://nunit3testexecutor/" className="CardValidation.Tests.Features.CreditCardValidationAPIFeature" name="ValidateCreditCard(&quot;Missing Owner&quot;,&quot;&quot;,&quot;4111111111111111&quot;,&quot;123&quot;,&quot;12/30&quot;,&quot;400&quot;,&quot;Owner&quot;,null)" />
    </UnitTest>
    <UnitTest name="ValidateCreditCard(&quot;Invalid Card Number&quot;,&quot;Test User&quot;,&quot;1234567890123456&quot;,&quot;123&quot;,&quot;12/30&quot;,&quot;400&quot;,&quot;Number&quot;,null)" storage="/app/cardvalidation.tests/bin/debug/net8.0/cardvalidation.tests.dll" id="78ff0762-a7af-0539-6b89-66a2e6a30f45">
      <Execution id="ef576f4c-2f5f-4122-9fb2-ec09726940de" />
      <TestMethod codeBase="/app/CardValidation.Tests/bin/Debug/net8.0/CardValidation.Tests.dll" adapterTypeName="executor://nunit3testexecutor/" className="CardValidation.Tests.Features.CreditCardValidationAPIFeature" name="ValidateCreditCard(&quot;Invalid Card Number&quot;,&quot;Test User&quot;,&quot;1234567890123456&quot;,&quot;123&quot;,&quot;12/30&quot;,&quot;400&quot;,&quot;Number&quot;,null)" />
    </UnitTest>
    <UnitTest name="ValidateCreditCard(&quot;CVV with special chars&quot;,&quot;Jane Doe&quot;,&quot;4111111111111111&quot;,&quot;12@#&quot;,&quot;12/30&quot;,&quot;400&quot;,&quot;Cvv&quot;,null)" storage="/app/cardvalidation.tests/bin/debug/net8.0/cardvalidation.tests.dll" id="68ca3ca2-1c1d-512a-bc13-db3d73a443a6">
      <Execution id="1934ec9b-2319-458f-b8ec-90db595efd44" />
      <TestMethod codeBase="/app/CardValidation.Tests/bin/Debug/net8.0/CardValidation.Tests.dll" adapterTypeName="executor://nunit3testexecutor/" className="CardValidation.Tests.Features.CreditCardValidationAPIFeature" name="ValidateCreditCard(&quot;CVV with special chars&quot;,&quot;Jane Doe&quot;,&quot;4111111111111111&quot;,&quot;12@#&quot;,&quot;12/30&quot;,&quot;400&quot;,&quot;Cvv&quot;,null)" />
    </UnitTest>
    <UnitTest name="ValidateCreditCard(&quot;Owner Contains Number&quot;,&quot;Jane 4111&quot;,&quot;4111111111111111&quot;,&quot;123&quot;,&quot;12/30&quot;,&quot;400&quot;,&quot;Owner&quot;,null)" storage="/app/cardvalidation.tests/bin/debug/net8.0/cardvalidation.tests.dll" id="f1411156-fa3a-66fd-3aeb-a831f0075505">
      <Execution id="36fe9e01-08a8-4b29-a0c2-39b966544754" />
      <TestMethod codeBase="/app/CardValidation.Tests/bin/Debug/net8.0/CardValidation.Tests.dll" adapterTypeName="executor://nunit3testexecutor/" className="CardValidation.Tests.Features.CreditCardValidationAPIFeature" name="ValidateCreditCard(&quot;Owner Contains Number&quot;,&quot;Jane 4111&quot;,&quot;4111111111111111&quot;,&quot;123&quot;,&quot;12/30&quot;,&quot;400&quot;,&quot;Owner&quot;,null)" />
    </UnitTest>
    <UnitTest name="ValidateCreditCard(&quot;Valid Visa Card&quot;,&quot;John Doe&quot;,&quot;4111111111111111&quot;,&quot;123&quot;,&quot;12/30&quot;,&quot;200&quot;,&quot;10&quot;,null)" storage="/app/cardvalidation.tests/bin/debug/net8.0/cardvalidation.tests.dll" id="16ef8a9a-364c-abcb-4047-0aefd08a7ca3">
      <Execution id="62267bad-1d56-4130-b6fc-b92e9a3877e3" />
      <TestMethod codeBase="/app/CardValidation.Tests/bin/Debug/net8.0/CardValidation.Tests.dll" adapterTypeName="executor://nunit3testexecutor/" className="CardValidation.Tests.Features.CreditCardValidationAPIFeature" name="ValidateCreditCard(&quot;Valid Visa Card&quot;,&quot;John Doe&quot;,&quot;4111111111111111&quot;,&quot;123&quot;,&quot;12/30&quot;,&quot;200&quot;,&quot;10&quot;,null)" />
    </UnitTest>
    <UnitTest name="ValidateCreditCard(&quot;Valid MasterCard&quot;,&quot;Alice Smith&quot;,&quot;5555555555554444&quot;,&quot;321&quot;,&quot;11/29&quot;,&quot;200&quot;,&quot;20&quot;,null)" storage="/app/cardvalidation.tests/bin/debug/net8.0/cardvalidation.tests.dll" id="1612b095-0679-bcfa-710a-560bf15c9807">
      <Execution id="6ee5c358-d7fb-4515-b155-8dd8c4e0b9b2" />
      <TestMethod codeBase="/app/CardValidation.Tests/bin/Debug/net8.0/CardValidation.Tests.dll" adapterTypeName="executor://nunit3testexecutor/" className="CardValidation.Tests.Features.CreditCardValidationAPIFeature" name="ValidateCreditCard(&quot;Valid MasterCard&quot;,&quot;Alice Smith&quot;,&quot;5555555555554444&quot;,&quot;321&quot;,&quot;11/29&quot;,&quot;200&quot;,&quot;20&quot;,null)" />
    </UnitTest>
    <UnitTest name="ValidateCreditCard(&quot;Expired Card Past Date&quot;,&quot;Expired User&quot;,&quot;4111111111111111&quot;,&quot;123&quot;,&quot;01/21&quot;,&quot;400&quot;,&quot;date&quot;,null)" storage="/app/cardvalidation.tests/bin/debug/net8.0/cardvalidation.tests.dll" id="68fac506-8cbd-2307-ddcc-118d3c5c55c2">
      <Execution id="79c1750e-37d1-4f4e-bb5e-a423fc6a62e3" />
      <TestMethod codeBase="/app/CardValidation.Tests/bin/Debug/net8.0/CardValidation.Tests.dll" adapterTypeName="executor://nunit3testexecutor/" className="CardValidation.Tests.Features.CreditCardValidationAPIFeature" name="ValidateCreditCard(&quot;Expired Card Past Date&quot;,&quot;Expired User&quot;,&quot;4111111111111111&quot;,&quot;123&quot;,&quot;01/21&quot;,&quot;400&quot;,&quot;date&quot;,null)" />
    </UnitTest>
  </TestDefinitions>
  <TestEntries>
    <TestEntry testId="63595178-fc82-5569-d94c-3932b3f89509" executionId="997a2069-1975-4861-b7c1-9d55ca740a91" testListId="8c84fa94-04c1-424b-9868-57a2d4851a1d" />
    <TestEntry testId="f1411156-fa3a-66fd-3aeb-a831f0075505" executionId="36fe9e01-08a8-4b29-a0c2-39b966544754" testListId="8c84fa94-04c1-424b-9868-57a2d4851a1d" />
    <TestEntry testId="59baaf00-14ab-9c15-2cf3-9c9f8aaf579c" executionId="85c17475-5bd8-4ffd-9321-967aee1449ff" testListId="8c84fa94-04c1-424b-9868-57a2d4851a1d" />
    <TestEntry testId="7b4e6a07-dd17-f5f2-ca6e-26619edc7e8c" executionId="67c27c6f-0e64-4220-acba-922a6b46bf3c" testListId="8c84fa94-04c1-424b-9868-57a2d4851a1d" />
    <TestEntry testId="470e68ea-e419-d394-555b-a31ecfd65e61" executionId="9fbecdf1-666d-4932-9433-8e1c4d57130e" testListId="8c84fa94-04c1-424b-9868-57a2d4851a1d" />
    <TestEntry testId="adc08fa8-fee9-a023-40ff-926214b51695" executionId="04275393-c4ba-451e-968a-fe69dbf59f6e" testListId="8c84fa94-04c1-424b-9868-57a2d4851a1d" />
    <TestEntry testId="20dc1195-9c36-e5e4-a77d-cef27585349b" executionId="b142d5de-7721-42c3-b6ed-18240813de3f" testListId="8c84fa94-04c1-424b-9868-57a2d4851a1d" />
    <TestEntry testId="68ca3ca2-1c1d-512a-bc13-db3d73a443a6" executionId="1934ec9b-2319-458f-b8ec-90db595efd44" testListId="8c84fa94-04c1-424b-9868-57a2d4851a1d" />
    <TestEntry testId="cff6bf2e-27b0-590e-ddb7-07789e0e8b71" executionId="20279186-7f4c-4207-8e18-d5e713f7d2a2" testListId="8c84fa94-04c1-424b-9868-57a2d4851a1d" />
    <TestEntry testId="11ed00b8-0216-ba7d-edf0-2178bbcf55bf" executionId="cc36a5e1-c853-4c13-8217-4c0f0f98be4c" testListId="8c84fa94-04c1-424b-9868-57a2d4851a1d" />
    <TestEntry testId="16ef8a9a-364c-abcb-4047-0aefd08a7ca3" executionId="62267bad-1d56-4130-b6fc-b92e9a3877e3" testListId="8c84fa94-04c1-424b-9868-57a2d4851a1d" />
    <TestEntry testId="ffd94f97-d161-5272-fc39-103757df0158" executionId="c53c8890-e03a-4571-9054-9d4a11f511f1" testListId="8c84fa94-04c1-424b-9868-57a2d4851a1d" />
    <TestEntry testId="68fac506-8cbd-2307-ddcc-118d3c5c55c2" executionId="79c1750e-37d1-4f4e-bb5e-a423fc6a62e3" testListId="8c84fa94-04c1-424b-9868-57a2d4851a1d" />
    <TestEntry testId="78ff0762-a7af-0539-6b89-66a2e6a30f45" executionId="ef576f4c-2f5f-4122-9fb2-ec09726940de" testListId="8c84fa94-04c1-424b-9868-57a2d4851a1d" />
    <TestEntry testId="b09f81a2-1945-73ea-e99d-fd5cb5d54e77" executionId="69e261b9-92c8-4124-82ec-02080131f6eb" testListId="8c84fa94-04c1-424b-9868-57a2d4851a1d" />
    <TestEntry testId="adf1ce10-4987-1f88-3692-e055f2ea7ce7" executionId="929e7eca-9eee-46ff-bb81-eaf357d3f200" testListId="8c84fa94-04c1-424b-9868-57a2d4851a1d" />
    <TestEntry testId="1612b095-0679-bcfa-710a-560bf15c9807" executionId="6ee5c358-d7fb-4515-b155-8dd8c4e0b9b2" testListId="8c84fa94-04c1-424b-9868-57a2d4851a1d" />
  </TestEntries>
  <TestLists>
    <TestList name="Results Not in a List" id="8c84fa94-04c1-424b-9868-57a2d4851a1d" />
    <TestList name="All Loaded Results" id="19431567-8539-422a-85d7-44ee4e166bda" />
  </TestLists>
  <ResultSummary outcome="Failed">
    <Counters total="17" executed="17" passed="0" failed="17" error="0" timeout="0" aborted="0" inconclusive="0" passedButRunAborted="0" notRunnable="0" notExecuted="0" disconnected="0" warning="0" completed="0" inProgress="0" pending="0" />
    <Output>
      <StdOut>NUnit Adapter 5.0.0.0: Test execution started
Running all tests in /app/CardValidation.Tests/bin/Debug/net8.0/CardValidation.Tests.dll
   NUnit3TestExecutor discovered 17 of 17 NUnit test cases using Current Discovery mode, Non-Explicit run
Given this is test case "Valid Visa Card"
API Base URL: http://localhost:7135
Running test case: Valid Visa Card
-&gt; done: CreditCardValidationSteps.GivenThisIsTestCase("Valid Visa Card") (0.0s)
And I prepare a credit card with:
  --- table step argument ---
  | Owner    | Number           | Cvv | IssueDate |
  | John Doe | 4111111111111111 | 123 | 12/30     |
-&gt; done: CreditCardValidationSteps.GivenIPrepareACreditCardWith(&lt;table&gt;) (0.0s)
When I send the card to the validation API
-&gt; done: CreditCardValidationSteps.WhenISendTheCardToTheValidationAPI() (0.0s)
Then the response status should be 200
-&gt; error: Exception has been thrown by the target of an invocation. (0.0s)
And the response body should contain "10"
-&gt; skipped because of previous errors
-&gt; duration: Scenario: Validate Credit Card: 163.6ms

Given this is test case "Valid MasterCard"
API Base URL: http://localhost:7135
Running test case: Valid MasterCard
-&gt; done: CreditCardValidationSteps.GivenThisIsTestCase("Valid MasterCard") (0.0s)
And I prepare a credit card with:
  --- table step argument ---
  | Owner       | Number           | Cvv | IssueDate |
  | Alice Smith | 5555555555554444 | 321 | 11/29     |
-&gt; done: CreditCardValidationSteps.GivenIPrepareACreditCardWith(&lt;table&gt;) (0.0s)
When I send the card to the validation API
-&gt; done: CreditCardValidationSteps.WhenISendTheCardToTheValidationAPI() (0.0s)
Then the response status should be 200
-&gt; error: Exception has been thrown by the target of an invocation. (0.0s)
And the response body should contain "20"
-&gt; skipped because of previous errors
-&gt; duration: Scenario: Validate Credit Card: 14.5ms

Given this is test case "Valid American Express"
API Base URL: http://localhost:7135
Running test case: Valid American Express
-&gt; done: CreditCardValidationSteps.GivenThisIsTestCase("Valid American Ex...") (0.0s)
And I prepare a credit card with:
  --- table step argument ---
  | Owner       | Number          | Cvv  | IssueDate |
  | Bob Johnson | 378282246310005 | 1234 | 06/28     |
-&gt; done: CreditCardValidationSteps.GivenIPrepareACreditCardWith(&lt;table&gt;) (0.0s)
When I send the card to the validation API
-&gt; done: CreditCardValidationSteps.WhenISendTheCardToTheValidationAPI() (0.0s)
Then the response status should be 200
-&gt; error: Exception has been thrown by the target of an invocation. (0.0s)
And the response body should contain "30"
-&gt; skipped because of previous errors
-&gt; duration: Scenario: Validate Credit Card: 12.4ms

Given this is test case "Missing Owner"
API Base URL: http://localhost:7135
Running test case: Missing Owner
-&gt; done: CreditCardValidationSteps.GivenThisIsTestCase("Missing Owner") (0.0s)
And I prepare a credit card with:
  --- table step argument ---
  | Owner | Number           | Cvv | IssueDate |
  |       | 4111111111111111 | 123 | 12/30     |
-&gt; done: CreditCardValidationSteps.GivenIPrepareACreditCardWith(&lt;table&gt;) (0.0s)
When I send the card to the validation API
-&gt; done: CreditCardValidationSteps.WhenISendTheCardToTheValidationAPI() (0.0s)
Then the response status should be 400
-&gt; error: Exception has been thrown by the target of an invocation. (0.0s)
And the response body should contain "Owner"
-&gt; skipped because of previous errors
-&gt; duration: Scenario: Validate Credit Card: 16.2ms

Given this is test case "Missing Number"
API Base URL: http://localhost:7135
Running test case: Missing Number
-&gt; done: CreditCardValidationSteps.GivenThisIsTestCase("Missing Number") (0.0s)
And I prepare a credit card with:
  --- table step argument ---
  | Owner    | Number | Cvv | IssueDate |
  | Jane Doe |        | 123 | 12/30     |
-&gt; done: CreditCardValidationSteps.GivenIPrepareACreditCardWith(&lt;table&gt;) (0.0s)
When I send the card to the validation API
-&gt; done: CreditCardValidationSteps.WhenISendTheCardToTheValidationAPI() (0.0s)
Then the response status should be 400
-&gt; error: Exception has been thrown by the target of an invocation. (0.0s)
And the response body should contain "Number"
-&gt; skipped because of previous errors
-&gt; duration: Scenario: Validate Credit Card: 12.5ms

Given this is test case "Missing CVV"
API Base URL: http://localhost:7135
Running test case: Missing CVV
-&gt; done: CreditCardValidationSteps.GivenThisIsTestCase("Missing CVV") (0.0s)
And I prepare a credit card with:
  --- table step argument ---
  | Owner    | Number           | Cvv | IssueDate |
  | Jane Doe | 4111111111111111 |     | 12/30     |
-&gt; done: CreditCardValidationSteps.GivenIPrepareACreditCardWith(&lt;table&gt;) (0.0s)
When I send the card to the validation API
-&gt; done: CreditCardValidationSteps.WhenISendTheCardToTheValidationAPI() (0.0s)
Then the response status should be 400
-&gt; error: Exception has been thrown by the target of an invocation. (0.0s)
And the response body should contain "Cvv"
-&gt; skipped because of previous errors
-&gt; duration: Scenario: Validate Credit Card: 19.0ms

Given this is test case "Missing IssueDate"
API Base URL: http://localhost:7135
Running test case: Missing IssueDate
-&gt; done: CreditCardValidationSteps.GivenThisIsTestCase("Missing IssueDate") (0.0s)
And I prepare a credit card with:
  --- table step argument ---
  | Owner    | Number           | Cvv | IssueDate |
  | Jane Doe | 4111111111111111 | 123 |           |
-&gt; done: CreditCardValidationSteps.GivenIPrepareACreditCardWith(&lt;table&gt;) (0.0s)
When I send the card to the validation API
-&gt; done: CreditCardValidationSteps.WhenISendTheCardToTheValidationAPI() (0.0s)
Then the response status should be 400
-&gt; error: Exception has been thrown by the target of an invocation. (0.0s)
And the response body should contain "date"
-&gt; skipped because of previous errors
-&gt; duration: Scenario: Validate Credit Card: 12.2ms

Given this is test case "Invalid Card Number"
API Base URL: http://localhost:7135
Running test case: Invalid Card Number
-&gt; done: CreditCardValidationSteps.GivenThisIsTestCase("Invalid Card Number") (0.0s)
And I prepare a credit card with:
  --- table step argument ---
  | Owner     | Number           | Cvv | IssueDate |
  | Test User | 1234567890123456 | 123 | 12/30     |
-&gt; done: CreditCardValidationSteps.GivenIPrepareACreditCardWith(&lt;table&gt;) (0.0s)
When I send the card to the validation API
-&gt; done: CreditCardValidationSteps.WhenISendTheCardToTheValidationAPI() (0.0s)
Then the response status should be 400
-&gt; error: Exception has been thrown by the target of an invocation. (0.0s)
And the response body should contain "Number"
-&gt; skipped because of previous errors
-&gt; duration: Scenario: Validate Credit Card: 14.1ms

Given this is test case "Invalid CVV length Visa"
API Base URL: http://localhost:7135
Running test case: Invalid CVV length Visa
-&gt; done: CreditCardValidationSteps.GivenThisIsTestCase("Invalid CVV lengt...") (0.0s)
And I prepare a credit card with:
  --- table step argument ---
  | Owner       | Number           | Cvv | IssueDate |
  | Clara Wells | 4111111111111111 | 12  | 12/30     |
-&gt; done: CreditCardValidationSteps.GivenIPrepareACreditCardWith(&lt;table&gt;) (0.0s)
When I send the card to the validation API
-&gt; done: CreditCardValidationSteps.WhenISendTheCardToTheValidationAPI() (0.0s)
Then the response status should be 400
-&gt; error: Exception has been thrown by the target of an invocation. (0.0s)
And the response body should contain "Cvv"
-&gt; skipped because of previous errors
-&gt; duration: Scenario: Validate Credit Card: 14.7ms

Given this is test case "Expired Card Past Date"
API Base URL: http://localhost:7135
Running test case: Expired Card Past Date
-&gt; done: CreditCardValidationSteps.GivenThisIsTestCase("Expired Card Past...") (0.0s)
And I prepare a credit card with:
  --- table step argument ---
  | Owner        | Number           | Cvv | IssueDate |
  | Expired User | 4111111111111111 | 123 | 01/21     |
-&gt; done: CreditCardValidationSteps.GivenIPrepareACreditCardWith(&lt;table&gt;) (0.0s)
When I send the card to the validation API
-&gt; done: CreditCardValidationSteps.WhenISendTheCardToTheValidationAPI() (0.0s)
Then the response status should be 400
-&gt; error: Exception has been thrown by the target of an invocation. (0.0s)
And the response body should contain "date"
-&gt; skipped because of previous errors
-&gt; duration: Scenario: Validate Credit Card: 22.3ms

Given this is test case "Owner Contains Number"
API Base URL: http://localhost:7135
Running test case: Owner Contains Number
-&gt; done: CreditCardValidationSteps.GivenThisIsTestCase("Owner Contains Nu...") (0.0s)
And I prepare a credit card with:
  --- table step argument ---
  | Owner     | Number           | Cvv | IssueDate |
  | Jane 4111 | 4111111111111111 | 123 | 12/30     |
-&gt; done: CreditCardValidationSteps.GivenIPrepareACreditCardWith(&lt;table&gt;) (0.0s)
When I send the card to the validation API
-&gt; done: CreditCardValidationSteps.WhenISendTheCardToTheValidationAPI() (0.0s)
Then the response status should be 400
-&gt; error: Exception has been thrown by the target of an invocation. (0.0s)
And the response body should contain "Owner"
-&gt; skipped because of previous errors
-&gt; duration: Scenario: Validate Credit Card: 15.9ms

Given this is test case "Owner Contains Card Number"
API Base URL: http://localhost:7135
Running test case: Owner Contains Card Number
-&gt; done: CreditCardValidationSteps.GivenThisIsTestCase("Owner Contains Ca...") (0.0s)
And I prepare a credit card with:
  --- table step argument ---
  | Owner        | Number           | Cvv | IssueDate |
  | John 4111111 | 4111111111111111 | 123 | 12/30     |
-&gt; done: CreditCardValidationSteps.GivenIPrepareACreditCardWith(&lt;table&gt;) (0.0s)
When I send the card to the validation API
-&gt; done: CreditCardValidationSteps.WhenISendTheCardToTheValidationAPI() (0.0s)
Then the response status should be 400
-&gt; error: Exception has been thrown by the target of an invocation. (0.0s)
And the response body should contain "Owner"
-&gt; skipped because of previous errors
-&gt; duration: Scenario: Validate Credit Card: 13.8ms

Given this is test case "CVV with special chars"
API Base URL: http://localhost:7135
Running test case: CVV with special chars
-&gt; done: CreditCardValidationSteps.GivenThisIsTestCase("CVV with special ...") (0.0s)
And I prepare a credit card with:
  --- table step argument ---
  | Owner    | Number           | Cvv  | IssueDate |
  | Jane Doe | 4111111111111111 | 12@# | 12/30     |
-&gt; done: CreditCardValidationSteps.GivenIPrepareACreditCardWith(&lt;table&gt;) (0.0s)
When I send the card to the validation API
-&gt; done: CreditCardValidationSteps.WhenISendTheCardToTheValidationAPI() (0.0s)
Then the response status should be 400
-&gt; error: Exception has been thrown by the target of an invocation. (0.0s)
And the response body should contain "Cvv"
-&gt; skipped because of previous errors
-&gt; duration: Scenario: Validate Credit Card: 20.8ms

Given this is test case "Card Number with spaces"
API Base URL: http://localhost:7135
Running test case: Card Number with spaces
-&gt; done: CreditCardValidationSteps.GivenThisIsTestCase("Card Number with ...") (0.0s)
And I prepare a credit card with:
  --- table step argument ---
  | Owner    | Number              | Cvv | IssueDate |
  | John Doe | 4111 1111 1111 1111 | 123 | 12/30     |
-&gt; done: CreditCardValidationSteps.GivenIPrepareACreditCardWith(&lt;table&gt;) (0.0s)
When I send the card to the validation API
-&gt; done: CreditCardValidationSteps.WhenISendTheCardToTheValidationAPI() (0.0s)
Then the response status should be 400
-&gt; error: Exception has been thrown by the target of an invocation. (0.0s)
And the response body should contain "Number"
-&gt; skipped because of previous errors
-&gt; duration: Scenario: Validate Credit Card: 13.4ms

Given this is test case "Invalid CVV and Date Format"
API Base URL: http://localhost:7135
Running test case: Invalid CVV and Date Format
-&gt; done: CreditCardValidationSteps.GivenThisIsTestCase("Invalid CVV and D...") (0.0s)
And I prepare a credit card with:
  --- table step argument ---
  | Owner    | Number           | Cvv | IssueDate |
  | John Doe | 4111111111111111 | 12  | 99-99     |
-&gt; done: CreditCardValidationSteps.GivenIPrepareACreditCardWith(&lt;table&gt;) (0.0s)
When I send the card to the validation API
-&gt; done: CreditCardValidationSteps.WhenISendTheCardToTheValidationAPI() (0.0s)
Then the response status should be 400
-&gt; error: Exception has been thrown by the target of an invocation. (0.0s)
And the response body should contain "{"Cvv":["Wrong cvv"],"Date":["Wrong date"]}"
-&gt; skipped because of previous errors
-&gt; duration: Scenario: Validate Credit Card: 16.4ms

Given this is test case "Invalid Owner and CVV"
API Base URL: http://localhost:7135
Running test case: Invalid Owner and CVV
-&gt; done: CreditCardValidationSteps.GivenThisIsTestCase("Invalid Owner and...") (0.0s)
And I prepare a credit card with:
  --- table step argument ---
  | Owner    | Number           | Cvv | IssueDate |
  | John 123 | 4111111111111111 | 12  | 12/30     |
-&gt; done: CreditCardValidationSteps.GivenIPrepareACreditCardWith(&lt;table&gt;) (0.0s)
When I send the card to the validation API
-&gt; done: CreditCardValidationSteps.WhenISendTheCardToTheValidationAPI() (0.0s)
Then the response status should be 400
-&gt; error: Exception has been thrown by the target of an invocation. (0.0s)
And the response body should contain "{"Cvv":["Wrong cvv"],"Owner":["Wrong owner"]}"
-&gt; skipped because of previous errors
-&gt; duration: Scenario: Validate Credit Card: 15.8ms

Given this is test case "Invalid All Fields"
API Base URL: http://localhost:7135
Running test case: Invalid All Fields
-&gt; done: CreditCardValidationSteps.GivenThisIsTestCase("Invalid All Fields") (0.0s)
And I prepare a credit card with:
  --- table step argument ---
  | Owner | Number | Cvv | IssueDate |
  |       | 123456 | abc | invalid   |
-&gt; done: CreditCardValidationSteps.GivenIPrepareACreditCardWith(&lt;table&gt;) (0.0s)
When I send the card to the validation API
-&gt; done: CreditCardValidationSteps.WhenISendTheCardToTheValidationAPI() (0.0s)
Then the response status should be 400
-&gt; error: Exception has been thrown by the target of an invocation. (0.0s)
And the response body should contain "{"Cvv":["Wrong cvv"],"Date":["Wrong date"],"Owner":["Owner is required"],"Number":["Wrong number"]}"
-&gt; skipped because of previous errors
-&gt; duration: Scenario: Validate Credit Card: 18.7ms

NUnit Adapter 5.0.0.0: Test execution complete
</StdOut>
    </Output>
  </ResultSummary>
</TestRun>